Workbook

Sheet Overall Writeoffs
A1: Vehicle ownership and Operation (Business only) | B1: 20676.13
A3: 1099 Employees
A4: Bryan | B4: 29578.02
A5: Jameson | B5: 0
A6: Casey | B6: 19616.47
A7: Tony | B7: 0
A9: Month | B9: Deposits | C9: Expenses | D9: Bill Pay | G9: Difference | H9: Car Write off | I9: Difference | J9: 1099 | K9: Total Loss
A10: January | B10: 7113.78 | C10: 11377.59 | D10: 8590
A11: February | B11: 0 | C11: 25311.08 | D11: 7205.5
A12: March | B12: 3575 | C12: 22238.06 | D12: 4008
A13: April | B13: 15160 | C13: 19902.05 | D13: 5128.23
A14: May | B14: 99479.82 | C14: 7739.21 | D14: 2350
A15: June | B15: 8705 | C15: 9820.15 | D15: 2155.35
A16: July | B16: 29245.94 | C16: 13960.55 | D16: 6482.06
A17: August | B17: 40112.38 | C17: 5191.33 | D17: 2658.02
A18: September | B18: 38566.18 | C18: 5088.45 | D18: 1400
A19: October | B19: 33110.82 | C19: 16792.53 | D19: 7614
A20: November | B20: 46059.53 | C20: 2446.6 | D20: 210
A21: December | B21: 68733.48 | C21: 1477.77 | D21: 1393.33
A22: Total | B22: =SUM(B10:B21) | C22: =SUM(C10:C21) | D22: =SUM(D10:D21) | G22: =B22-C22-D22 | H22: 20676.13 | I22: =G22-H22 | J22: =SUM(B4:B7) | K22: =I22-J22

Sheet RAW_2025
A1: Date | B1: Description | C1: Amount | D1: Type
A2: 45659 | B2: Card Withdrawals - Debit Purchase - VISA On 123124 800-956-6310 IL 6122674711 $ | C2: 409.37 | D2: Debit
A3: 45659 | B3: Other Withdrawals - Zelle Instant PMT To Nadia Session $ | C3: 247 | D3: Debit
A4: 45660 | B4: Other Withdrawals - Zelle Instant PMT To Brian Davis | C4: 1120 | D4: Debit
A5: 45660 | B5: Other Withdrawals - Zelle Instant PMT To Casey Williamson | C5: 600 | D5: Debit
A6: 45663 | B6: Other Withdrawals - Electronic Withdrawal To CEFCU TEL DEBIT | C6: 1042.46 | D6: Debit
A7: 45664 | B7: Other Withdrawals - Mobile Banking Transfer To Account 152316874980 | C7: 15 | D7: Debit
A8: 45665 | B8: Card Withdrawals - Debit Purchase - VISA On 010725 O FALLON IL 7001446395 | C8: 2.19 | D8: Debit
A9: 45665 | B9: Other Deposits - Debit Purchase Ret - VISA On 010725 8664244197 IL 7063781288 $ | C9: 13.78 | D9: Credit
A10: 45665 | B10: Other Withdrawals - Electronic Withdrawal To Mission Lane LLC | C10: 67.44 | D10: Debit
A11: 45666 | B11: Card Withdrawals - Debit Purchase - VISA On 010725 618-2869595 IL 8109867096 | C11: 440 | D11: Debit
A12: 45666 | B12: Other Withdrawals - Zelle Instant PMT To Brian Davis | C12: 80 | D12: Debit
A13: 45667 | B13: Card Withdrawals - Debit Purchase MOTOMART FREEBURG IL | C13: 61.97 | D13: Debit
... A576: 46000 | B576: Other Withdrawals - Mobile Banking Transfer To Account 152316875235 | C576: 200 | D576: Debit

Sheet CATEGORIZED_2025
A1: Date | B1: Description | C1: Amount | D1: Type | E1: Category | F1: Original Group | G1: Final Group | H1: Manual Override | I1: Override Note | J1: Contractor | L1: WARNING: Changing Final Group may impact tax reporting. Confirm with tax professional.
A2: 45659 | B2: Card Withdrawals - Debit Purchase - VISA On 123124 800-956-6310 IL 6122674711 $ | C2: 409.37 | D2: Debit | E2: Tools | F2: =IF(E2="Income","Revenue",IF(OR(E2="Materials",E2="Labor",E2="Dump Fees"),"COGS",IF(OR(E2="Fuel",E2="Insurance",E2="Tools",E2="Repairs"),"Expense","Non-Deductible"))) | G2: Expense | H2: =IF(G2<>F2,"YES","NO")
A3: 45659 | B3: Other Withdrawals - Zelle Instant PMT To Nadia Session $ | C3: 247 | D3: Debit | E3: Tools | F3: =IF(E3="Income","Revenue",IF(OR(E3="Materials",E3="Labor",E3="Dump Fees"),"COGS",IF(OR(E3="Fuel",E3="Insurance",E3="Tools",E3="Repairs"),"Expense","Non-Deductible"))) | G3: Expense | H3: =IF(G3<>F3,"YES","NO")
A4: 45660 | B4: Other Withdrawals - Zelle Instant PMT To Brian Davis | C4: 1120 | D4: Debit | E4: Labor | F4: =IF(E4="Income","Revenue",IF(OR(E4="Materials",E4="Labor",E4="Dump Fees"),"COGS",IF(OR(E4="Fuel",E4="Insurance",E4="Tools",E4="Repairs"),"Expense","Non-Deductible"))) | G4: COGS | H4: =IF(G4<>F4,"YES","NO") | J4: Bryan
A5: 45660 | B5: Other Withdrawals - Zelle Instant PMT To Casey Williamson | C5: 600 | D5: Debit | E5: Labor | F5: =IF(E5="Income","Revenue",IF(OR(E5="Materials",E5="Labor",E5="Dump Fees"),"COGS",IF(OR(E5="Fuel",E5="Insurance",E5="Tools",E5="Repairs"),"Expense","Non-Deductible"))) | G5: COGS | H5: =IF(G5<>F5,"YES","NO") | J5: Casey
A6: 45663 | B6: Other Withdrawals - Electronic Withdrawal To CEFCU TEL DEBIT | C6: 1042.46 | D6: Debit | E6: Tools | F6: =IF(E6="Income","Revenue",IF(OR(E6="Materials",E6="Labor",E6="Dump Fees"),"COGS",IF(OR(E6="Fuel",E6="Insurance",E6="Tools",E6="Repairs"),"Expense","Non-Deductible"))) | G6: Expense | H6: =IF(G6<>F6,"YES","NO")
A7: 45664 | B7: Other Withdrawals - Mobile Banking Transfer To Account 152316874980 | C7: 15 | D7: Debit | E7: Transfer | F7: =IF(E7="Income","Revenue",IF(OR(E7="Materials",E7="Labor",E7="Dump Fees"),"COGS",IF(OR(E7="Fuel",E7="Insurance",E7="Tools",E7="Repairs"),"Expense","Non-Deductible"))) | G7: Non-Deductible | H7: =IF(G7<>F7,"YES","NO")
A8: 45665 | B8: Card Withdrawals - Debit Purchase - VISA On 010725 O FALLON IL 7001446395 | C8: 2.19 | D8: Debit | E8: Tools | F8: =IF(E8="Income","Revenue",IF(OR(E8="Materials",E8="Labor",E8="Dump Fees"),"COGS",IF(OR(E8="Fuel",E8="Insurance",E8="Tools",E8="Repairs"),"Expense","Non-Deductible"))) | G8: Expense | H8: =IF(G8<>F8,"YES","NO")
A9: 45665 | B9: Other Deposits - Debit Purchase Ret - VISA On 010725 8664244197 IL 7063781288 $ | C9: 13.78 | D9: Credit | E9: Income | F9: =IF(E9="Income","Revenue",IF(OR(E9="Materials",E9="Labor",E9="Dump Fees"),"COGS",IF(OR(E9="Fuel",E9="Insurance",E9="Tools",E9="Repairs"),"Expense","Non-Deductible"))) | G9: Revenue | H9: =IF(G9<>F9,"YES","NO")
A10: 45665 | B10: Other Withdrawals - Electronic Withdrawal To Mission Lane LLC | C10: 67.44 | D10: Debit | E10: Tools | F10: =IF(E10="Income","Revenue",IF(OR(E10="Materials",E10="Labor",E10="Dump Fees"),"COGS",IF(OR(E10="Fuel",E10="Insurance",E10="Tools",E10="Repairs"),"Expense","Non-Deductible"))) | G10: Expense | H10: =IF(G10<>F10,"YES","NO")
A11: 45666 | B11: Card Withdrawals - Debit Purchase - VISA On 010725 618-2869595 IL 8109867096 | C11: 440 | D11: Debit | E11: Tools | F11: =IF(E11="Income","Revenue",IF(OR(E11="Materials",E11="Labor",E11="Dump Fees"),"COGS",IF(OR(E11="Fuel",E11="Insurance",E11="Tools",E11="Repairs"),"Expense","Non-Deductible"))) | G11: Expense | H11: =IF(G11<>F11,"YES","NO")
A12: 45666 | B12: Other Withdrawals - Zelle Instant PMT To Brian Davis | C12: 80 | D12: Debit | E12: Labor | F12: =IF(E12="Income","Revenue",IF(OR(E12="Materials",E12="Labor",E12="Dump Fees"),"COGS",IF(OR(E12="Fuel",E12="Insurance",E12="Tools",E12="Repairs"),"Expense","Non-Deductible"))) | G12: COGS | H12: =IF(G12<>F12,"YES","NO") | J12: Bryan
A13: 45667 | B13: Card Withdrawals - Debit Purchase MOTOMART FREEBURG IL | C13: 61.97 | D13: Debit | E13: Tools | F13: =IF(E13="Income","Revenue",IF(OR(E13="Materials",E13="Labor",E13="Dump Fees"),"COGS",IF(OR(E13="Fuel",E13="Insurance",E13="Tools",E13="Repairs"),"Expense","Non-Deductible"))) | G13: Expense | H13: =IF(G13<>F13,"YES","NO")
A14: 45667 | B14: Other Withdrawals - Mobile Banking Transfer To Account 152316875235 | C14: 300 | D14: Debit | E14: Transfer | F14: =IF(E14="Income","Revenue",IF(OR(E14="Materials",E14="Labor",E14="Dump Fees"),"COGS",IF(OR(E14="Fuel",E14="Insurance",E14="Tools",E14="Repairs"),"Expense","Non-Deductible"))) | G14: Non-Deductible | H14: =IF(G14<>F14,"YES","NO")
A15: 45667 | B15: Other Withdrawals - Zelle Instant PMT To Brian Davis | C15: 945 | D15: Debit | E15: Labor | F15: =IF(E15="Income","Revenue",IF(OR(E15="Materials",E15="Labor",E15="Dump Fees"),"COGS",IF(OR(E15="Fuel",E15="Insurance",E15="Tools",E15="Repairs"),"Expense","Non-Deductible"))) | G15: COGS | H15: =IF(G15<>F15,"YES","NO") | J15: Bryan
A16: 45667 | B16: Other Withdrawals - Zelle Instant PMT To Casey Williamson | C16: 575 | D16: Debit | E16: Labor | F16: =IF(E16="Income","Revenue",IF(OR(E16="Materials",E16="Labor",E16="Dump Fees"),"COGS",IF(OR(E16="Fuel",E16="Insurance",E16="Tools",E16="Repairs"),"Expense","Non-Deductible"))) | G16: COGS | H16: =IF(G16<>F16,"YES","NO") | J16: Casey
A17: 45670 | B17: Card Withdrawals - ATM Withdrawal 300 S GREEN MOUN BELLEVILLE IL | C17: 103.95 | D17: Debit | E17: Tools | F17: =IF(E17="Income","Revenue",IF(OR(E17="Materials",E17="Labor",E17="Dump Fees"),"COGS",IF(OR(E17="Fuel",E17="Insurance",E17="Tools",E17="Repairs"),"Expense","Non-Deductible"))) | G17: Expense | H17: =IF(G17<>F17,"YES","NO")
A18: 45670 | B18: Card Withdrawals - Debit Purchase - VISA On 011125 Visa Direct NY 1000183320 | C18: 100 | D18: Debit | E18: Tools | F18: =IF(E18="Income","Revenue",IF(OR(E18="Materials",E18="Labor",E18="Dump Fees"),"COGS",IF(OR(E18="Fuel",E18="Insurance",E18="Tools",E18="Repairs"),"Expense","Non-Deductible"))) | G18: Expense | H18: =IF(G18<>F18,"YES","NO")
A19: 45670 | B19: Card Withdrawals - Debit Purchase CIRCLE K # 01361 BELLEVILLE IL | C19: 27.01 | D19: Debit | E19: Tools | F19: =IF(E19="Income","Revenue",IF(OR(E19="Materials",E19="Labor",E19="Dump Fees"),"COGS",IF(OR(E19="Fuel",E19="Insurance",E19="Tools",E19="Repairs"),"Expense","Non-Deductible"))) | G19: Expense | H19: =IF(G19<>F19,"YES","NO")
A20: 45670 | B20: Card Withdrawals - Debit Purchase MOTOMART FREEBURG IL | C20: 87.64 | D20: Debit | E20: Tools | F20: =IF(E20="Income","Revenue",IF(OR(E20="Materials",E20="Labor",E20="Dump Fees"),"COGS",IF(OR(E20="Fuel",E20="Insurance",E20="Tools",E20="Repairs"),"Expense","Non-Deductible"))) | G20: Expense | H20: =IF(G20<>F20,"YES","NO")
A21: 45670 | B21: Card Withdrawals - Debit Purchase THE HOME DEPOT # BELLEVILLE IL 6901111158 | C21: 371.21 | D21: Debit | E21: Materials | F21: =IF(E21="Income","Revenue",IF(OR(E21="Materials",E21="Labor",E21="Dump Fees"),"COGS",IF(OR(E21="Fuel",E21="Insurance",E21="Tools",E21="Repairs"),"Expense","Non-Deductible"))) | G21: COGS | H21: =IF(G21<>F21,"YES","NO")
A22: 45670 | B22: Card Withdrawals - Fee ATM Withdrawal At Other Network 1300000717 $ | C22: 2.5 | D22: Debit | E22: Tools | F22: =IF(E22="Income","Revenue",IF(OR(E22="Materials",E22="Labor",E22="Dump Fees"),"COGS",IF(OR(E22="Fuel",E22="Insurance",E22="Tools",E22="Repairs"),"Expense","Non-Deductible"))) | G22: Expense | H22: =IF(G22<>F22,"YES","NO")
A23: 45670 | B23: Other Withdrawals - Electronic Withdrawal To MERCURY CARD FBT | C23: 573.53 | D23: Debit | E23: Tools | F23: =IF(E23="Income","Revenue",IF(OR(E23="Materials",E23="Labor",E23="Dump Fees"),"COGS",IF(OR(E23="Fuel",E23="Insurance",E23="Tools",E23="Repairs"),"Expense","Non-Deductible"))) | G23: Expense | H23: =IF(G23<>F23,"YES","NO")
A24: 45672 | B24: Card Withdrawals - Debit Purchase - VISA On 011425 618-2330303 IL 5006499752 | C24: 74.54 | D24: Debit | E24: Tools | F24: =IF(E24="Income","Revenue",IF(OR(E24="Materials",E24="Labor",E24="Dump Fees"),"COGS",IF(OR(E24="Fuel",E24="Insurance",E24="Tools",E24="Repairs"),"Expense","Non-Deductible"))) | G24: Expense | H24: =IF(G24<>F24,"YES","NO")
A25: 45672 | B25: Card Withdrawals - Debit Purchase - VISA On 011425 FREEBURG IL 4720240094 | C25: 3.6 | D25: Debit | E25: Tools | F25: =IF(E25="Income","Revenue",IF(OR(E25="Materials",E25="Labor",E25="Dump Fees"),"COGS",IF(OR(E25="Fuel",E25="Insurance",E25="Tools",E25="Repairs"),"Expense","Non-Deductible"))) | G25: Expense | H25: =IF(G25<>F25,"YES","NO")
A26: 45672 | B26: Card Withdrawals - Debit Purchase CIRCLE K # 01343 SHILOH IL | C26: 28.98 | D26: Debit | E26: Tools | F26: =IF(E26="Income","Revenue",IF(OR(E26="Materials",E26="Labor",E26="Dump Fees"),"COGS",IF(OR(E26="Fuel",E26="Insurance",E26="Tools",E26="Repairs"),"Expense","Non-Deductible"))) | G26: Expense | H26: =IF(G26<>F26,"YES","NO")
A27: 45672 | B27: Other Deposits - Mobile Check Deposit 8613623522 | C27: 4400 | D27: Credit | E27: Income | F27: =IF(E27="Income","Revenue",IF(OR(E27="Materials",E27="Labor",E27="Dump Fees"),"COGS",IF(OR(E27="Fuel",E27="Insurance",E27="Tools",E27="Repairs"),"Expense","Non-Deductible"))) | G27: Revenue | H27: =IF(G27<>F27,"YES","NO")
A28: 45672 | B28: Other Withdrawals - Analysis Service Charge 1600000000 | C28: 16 | D28: Debit | E28: Repairs | F28: =IF(E28="Income","Revenue",IF(OR(E28="Materials",E28="Labor",E28="Dump Fees"),"COGS",IF(OR(E28="Fuel",E28="Insurance",E28="Tools",E28="Repairs"),"Expense","Non-Deductible"))) | G28: Expense | H28: =IF(G28<>F28,"YES","NO")
... A39: 45674 | B39: Other Withdrawals - Electronic Withdrawal To MIDLAND MTG | C39: 1089.56 | D39: Debit | E39: Tools | F39: =IF(E39="Income","Revenue",IF(OR(E39="Materials",E39="Labor",E39="Dump Fees"),"COGS",IF(OR(E39="Fuel",E39="Insurance",E39="Tools",E39="Repairs"),"Expense","Non-Deductible"))) | G39: Expense | H39: =IF(G39<>F39,"YES","NO")
A40: 45674 | B40: Other Withdrawals - Zelle Instant PMT To BRIAN DAVIS | C40: 1330 | D40: Debit | E40: Labor | F40: =IF(E40="Income","Revenue",IF(OR(E40="Materials",E40="Labor",E40="Dump Fees"),"COGS",IF(OR(E40="Fuel",E40="Insurance",E40="Tools",E40="Repairs"),"Expense","Non-Deductible"))) | G40: COGS | H40: =IF(G40<>F40,"YES","NO") | J40: Bryan
A41: 45674 | B41: Other Withdrawals - Zelle Instant PMT To Casey Williamson | C41: 600 | D41: Debit | E41: Labor | F41: =IF(E41="Income","Revenue",IF(OR(E41="Materials",E41="Labor",E41="Dump Fees"),"COGS",IF(OR(E41="Fuel",E41="Insurance",E41="Tools",E41="Repairs"),"Expense","Non-Deductible"))) | G41: COGS | H41: =IF(G41<>F41,"YES","NO") | J41: Casey
A42: 45674 | B42: Other Withdrawals - Zelle Instant PMT To Nadia Session | C42: 100 | D42: Debit | E42: Tools | F42: =IF(E42="Income","Revenue",IF(OR(E42="Materials",E42="Labor",E42="Dump Fees"),"COGS",IF(OR(E42="Fuel",E42="Insurance",E42="Tools",E42="Repairs"),"Expense","Non-Deductible"))) | G42: Expense | H42: =IF(G42<>F42,"YES","NO")
A43: 45678 | B43: Card Withdrawals - Debit Purchase DOLLAR-GENERAL # FREEBURG IL 2301191431 | C43: 87.41 | D43: Debit | E43: Tools | F43: =IF(E43="Income","Revenue",IF(OR(E43="Materials",E43="Labor",E43="Dump Fees"),"COGS",IF(OR(E43="Fuel",E43="Insurance",E43="Tools",E43="Repairs"),"Expense","Non-Deductible"))) | G43: Expense | H43: =IF(G43<>F43,"YES","NO")
A44: 45678 | B44: Card Withdrawals - Debit Purchase verifyvend855-55 PROVIDENCE RI 1201201605 | C44: 236 | D44: Debit | E44: Tools | F44: =IF(E44="Income","Revenue",IF(OR(E44="Materials",E44="Labor",E44="Dump Fees"),"COGS",IF(OR(E44="Fuel",E44="Insurance",E44="Tools",E44="Repairs"),"Expense","Non-Deductible"))) | G44: Expense | H44: =IF(G44<>F44,"YES","NO")
A45: 45680 | B45: Other Withdrawals - Mobile Banking Transfer To Account 152316874980 | C45: 66 | D45: Debit | E45: Transfer | F45: =IF(E45="Income","Revenue",IF(OR(E45="Materials",E45="Labor",E45="Dump Fees"),"COGS",IF(OR(E45="Fuel",E45="Insurance",E45="Tools",E45="Repairs"),"Expense","Non-Deductible"))) | G45: Non-Deductible | H45: =IF(G45<>F45,"YES","NO")
A46: 45681 | B46: Other Withdrawals - Mobile Banking Transfer To Account 152316875235 | C46: 850 | D46: Debit | E46: Transfer | F46: =IF(E46="Income","Revenue",IF(OR(E46="Materials",E46="Labor",E46="Dump Fees"),"COGS",IF(OR(E46="Fuel",E46="Insurance",E46="Tools",E46="Repairs"),"Expense","Non-Deductible"))) | G46: Non-Deductible | H46: =IF(G46<>F46,"YES","NO")
A47: 45681 | B47: Other Withdrawals - Zelle Instant PMT To Brian Davis | C47: 890 | D47: Debit | E47: Labor | F47: =IF(E47="Income","Revenue",IF(OR(E47="Materials",E47="Labor",E47="Dump Fees"),"COGS",IF(OR(E47="Fuel",E47="Insurance",E47="Tools",E47="Repairs"),"Expense","Non-Deductible"))) | G47: COGS | H47: =IF(G47<>F47,"YES","NO") | J47: Bryan
A48: 45681 | B48: Other Withdrawals - Zelle Instant PMT To Casey Williamson | C48: 200 | D48: Debit | E48: Labor | F48: =IF(E48="Income","Revenue",IF(OR(E48="Materials",E48="Labor",E48="Dump Fees"),"COGS",IF(OR(E48="Fuel",E48="Insurance",E48="Tools",E48="Repairs"),"Expense","Non-Deductible"))) | G48: COGS | H48: =IF(G48<>F48,"YES","NO") | J48: Casey
A49: 45684 | B49: Card Withdrawals - Debit Purchase MOTOMART FREEBURG IL | C49: 86.57 | D49: Debit | E49: Tools | F49: =IF(E49="Income","Revenue",IF(OR(E49="Materials",E49="Labor",E49="Dump Fees"),"COGS",IF(OR(E49="Fuel",E49="Insurance",E49="Tools",E49="Repairs"),"Expense","Non-Deductible"))) | G49: Expense | H49: =IF(G49<>F49,"YES","NO")
A50: 45684 | B50: Card Withdrawals - Recurring Debit Purchase On 012525 888-270-2644 IN 6101039921 | C50: 817.5 | D50: Debit | E50: Tools | F50: =IF(E50="Income","Revenue",IF(OR(E50="Materials",E50="Labor",E50="Dump Fees"),"COGS",IF(OR(E50="Fuel",E50="Insurance",E50="Tools",E50="Repairs"),"Expense","Non-Deductible"))) | G50: Expense | H50: =IF(G50<>F50,"YES","NO")
...

Sheet P&L_2025
A1: ALL PRO METRO EAST CONSTRUCTION LLC - Profit & Loss 2025
A3: Revenue | B3: =SUMIFS(CATEGORIZED_2025!$C:$C,CATEGORIZED_2025!$G:$G,"Revenue")
A4: COGS | B4: =SUMIFS(CATEGORIZED_2025!$C:$C,CATEGORIZED_2025!$G:$G,"COGS")
A5: Expenses | B5: =SUMIFS(CATEGORIZED_2025!$C:$C,CATEGORIZED_2025!$G:$G,"Expense")
A6: Non-Deductible | B6: =SUMIFS(CATEGORIZED_2025!$C:$C,CATEGORIZED_2025!$G:$G,"Non-Deductible")
A7: Net Income | B7: =B3-B4-B5
A8: Manual Overrides | B8: =COUNTIF(CATEGORIZED_2025!$H:$H,"YES")

Sheet MONTHLY_2025
A1: Month | B1: Revenue | C1: COGS | D1: Expenses | E1: Net Income
A2: January | B2: =SUMPRODUCT((CATEGORIZED_2025!$G$2:$G$200000="Revenue")*(TEXT(CATEGORIZED_2025!$A$2:$A$200000,"yyyy-mm")="2025-01")*CATEGORIZED_2025!$C$2:$C$200000) | C2: =SUMPRODUCT((CATEGORIZED_2025!$G$2:$G$200000="COGS")*(TEXT(CATEGORIZED_2025!$A$2:$A$200000,"yyyy-mm")="2025-01")*CATEGORIZED_2025!$C$2:$C$200000) | D2: =SUMPRODUCT((CATEGORIZED_2025!$G$2:$G$200000="Expense")*(TEXT(CATEGORIZED_2025!$A$2:$A$200000,"yyyy-mm")="2025-01")*CATEGORIZED_2025!$C$2:$C$200000) | E2: =B2-C2-D2
A3: February | B3: =SUMPRODUCT((CATEGORIZED_2025!$G$2:$G$200000="Revenue")*(TEXT(CATEGORIZED_2025!$A$2:$A$200000,"yyyy-mm")="2025-02")*CATEGORIZED_2025!$C$2:$C$200000) | C3: =SUMPRODUCT((CATEGORIZED_2025!$G$2:$G$200000="COGS")*(TEXT(CATEGORIZED_2025!$A$2:$A$200000,"yyyy-mm")="2025-02")*CATEGORIZED_2025!$C$2:$C$200000) | D3: =SUMPRODUCT((CATEGORIZED_2025!$G$2:$G$200000="Expense")*(TEXT(CATEGORIZED_2025!$A$2:$A$200000,"yyyy-mm")="2025-02")*CATEGORIZED_2025!$C$2:$C$200000) | E3: =B3-C3-D3
A4: March | B4: =SUMPRODUCT((CATEGORIZED_2025!$G$2:$G$200000="Revenue")*(TEXT(CATEGORIZED_2025!$A$2:$A$200000,"yyyy-mm")="2025-03")*CATEGORIZED_2025!$C$2:$C$200000) | C4: =SUMPRODUCT((CATEGORIZED_2025!$G$2:$G$200000="COGS")*(TEXT(CATEGORIZED_2025!$A$2:$A$200000,"yyyy-mm")="2025-03")*CATEGORIZED_2025!$C$2:$C$200000) | D4: =SUMPRODUCT((CATEGORIZED_2025!$G$2:$G$200000="Expense")*(TEXT(CATEGORIZED_2025!$A$2:$A$200000,"yyyy-mm")="2025-03")*CATEGORIZED_2025!$C$2:$C$200000) | E4: =B4-C4-D4
A5: April | B5: =SUMPRODUCT((CATEGORIZED_2025!$G$2:$G$200000="Revenue")*(TEXT(CATEGORIZED_2025!$A$2:$A$200000,"yyyy-mm")="2025-04")*CATEGORIZED_2025!$C$2:$C$200000) | C5: =SUMPRODUCT((CATEGORIZED_2025!$G$2:$G$200000="COGS")*(TEXT(CATEGORIZED_2025!$A$2:$A$200000,"yyyy-mm")="2025-04")*CATEGORIZED_2025!$C$2:$C$200000) | D5: =SUMPRODUCT((CATEGORIZED_2025!$G$2:$G$200000="Expense")*(TEXT(CATEGORIZED_2025!$A$2:$A$200000,"yyyy-mm")="2025-04")*CATEGORIZED_2025!$C$2:$C$200000) | E5: =B5-C5-D5
A6: May | B6: =SUMPRODUCT((CATEGORIZED_2025!$G$2:$G$200000="Revenue")*(TEXT(CATEGORIZED_2025!$A$2:$A$200000,"yyyy-mm")="2025-05")*CATEGORIZED_2025!$C$2:$C$200000) | C6: =SUMPRODUCT((CATEGORIZED_2025!$G$2:$G$200000="COGS")*(TEXT(CATEGORIZED_2025!$A$2:$A$200000,"yyyy-mm")="2025-05")*CATEGORIZED_2025!$C$2:$C$200000) | D6: =SUMPRODUCT((CATEGORIZED_2025!$G$2:$G$200000="Expense")*(TEXT(CATEGORIZED_2025!$A$2:$A$200000,"yyyy-mm")="2025-05")*CATEGORIZED_2025!$C$2:$C$200000) | E6: =B6-C6-D6
A7: June | B7: =SUMPRODUCT((CATEGORIZED_2025!$G$2:$G$200000="Revenue")*(TEXT(CATEGORIZED_2025!$A$2:$A$200000,"yyyy-mm")="2025-06")*CATEGORIZED_2025!$C$2:$C$200000) | C7: =SUMPRODUCT((CATEGORIZED_2025!$G$2:$G$200000="COGS")*(TEXT(CATEGORIZED_2025!$A$2:$A$200000,"yyyy-mm")="2025-06")*CATEGORIZED_2025!$C$2:$C$200000) | D7: =SUMPRODUCT((CATEGORIZED_2025!$G$2:$G$200000="Expense")*(TEXT(CATEGORIZED_2025!$A$2:$A$200000,"yyyy-mm")="2025-06")*CATEGORIZED_2025!$C$2:$C$200000) | E7: =B7-C7-D7
A8: July | B8: =SUMPRODUCT((CATEGORIZED_2025!$G$2:$G$200000="Revenue")*(TEXT(CATEGORIZED_2025!$A$2:$A$200000,"yyyy-mm")="2025-07")*CATEGORIZED_2025!$C$2:$C$200000) | C8: =SUMPRODUCT((CATEGORIZED_2025!$G$2:$G$200000="COGS")*(TEXT(CATEGORIZED_2025!$A$2:$A$200000,"yyyy-mm")="2025-07")*CATEGORIZED_2025!$C$2:$C$200000) | D8: =SUMPRODUCT((CATEGORIZED_2025!$G$2:$G$200000="Expense")*(TEXT(CATEGORIZED_2025!$A$2:$A$200000,"yyyy-mm")="2025-07")*CATEGORIZED_2025!$C$2:$C$200000) | E8: =B8-C8-D8
A9: August | B9: =SUMPRODUCT((CATEGORIZED_2025!$G$2:$G$200000="Revenue")*(TEXT(CATEGORIZED_2025!$A$2:$A$200000,"yyyy-mm")="2025-08")*CATEGORIZED_2025!$C$2:$C$200000) | C9: =SUMPRODUCT((CATEGORIZED_2025!$G$2:$G$200000="COGS")*(TEXT(CATEGORIZED_2025!$A$2:$A$200000,"yyyy-mm")="2025-08")*CATEGORIZED_2025!$C$2:$C$200000) | D9: =SUMPRODUCT((CATEGORIZED_2025!$G$2:$G$200000="Expense")*(TEXT(CATEGORIZED_2025!$A$2:$A$200000,"yyyy-mm")="2025-08")*CATEGORIZED_2025!$C$2:$C$200000) | E9: =B9-C9-D9
A10: September | B10: =SUMPRODUCT((CATEGORIZED_2025!$G$2:$G$200000="Revenue")*(TEXT(CATEGORIZED_2025!$A$2:$A$200000,"yyyy-mm")="2025-09")*CATEGORIZED_2025!$C$2:$C$200000) | C10: =SUMPRODUCT((CATEGORIZED_2025!$G$2:$G$200000="COGS")*(TEXT(CATEGORIZED_2025!$A$2:$A$200000,"yyyy-mm")="2025-09")*CATEGORIZED_2025!$C$2:$C$200000) | D10: =SUMPRODUCT((CATEGORIZED_2025!$G$2:$G$200000="Expense")*(TEXT(CATEGORIZED_2025!$A$2:$A$200000,"yyyy-mm")="2025-09")*CATEGORIZED_2025!$C$2:$C$200000) | E10: =B10-C10-D10
A11: October | B11: =SUMPRODUCT((CATEGORIZED_2025!$G$2:$G$200000="Revenue")*(TEXT(CATEGORIZED_2025!$A$2:$A$200000,"yyyy-mm")="2025-10")*CATEGORIZED_2025!$C$2:$C$200000) | C11: =SUMPRODUCT((CATEGORIZED_2025!$G$2:$G$200000="COGS")*(TEXT(CATEGORIZED_2025!$A$2:$A$200000,"yyyy-mm")="2025-10")*CATEGORIZED_2025!$C$2:$C$200000) | D11: =SUMPRODUCT((CATEGORIZED_2025!$G$2:$G$200000="Expense")*(TEXT(CATEGORIZED_2025!$A$2:$A$200000,"yyyy-mm")="2025-10")*CATEGORIZED_2025!$C$2:$C$200000) | E11: =B11-C11-D11
A12: November | B12: =SUMPRODUCT((CATEGORIZED_2025!$G$2:$G$200000="Revenue")*(TEXT(CATEGORIZED_2025!$A$2:$A$200000,"yyyy-mm")="2025-11")*CATEGORIZED_2025!$C$2:$C$200000) | C12: =SUMPRODUCT((CATEGORIZED_2025!$G$2:$G$200000="COGS")*(TEXT(CATEGORIZED_2025!$A$2:$A$200000,"yyyy-mm")="2025-11")*CATEGORIZED_2025!$C$2:$C$200000) | D12: =SUMPRODUCT((CATEGORIZED_2025!$G$2:$G$200000="Expense")*(TEXT(CATEGORIZED_2025!$A$2:$A$200000,"yyyy-mm")="2025-11")*CATEGORIZED_2025!$C$2:$C$200000) | E12: =B12-C12-D12
A13: December | B13: =SUMPRODUCT((CATEGORIZED_2025!$G$2:$G$200000="Revenue")*(TEXT(CATEGORIZED_2025!$A$2:$A$200000,"yyyy-mm")="2025-12")*CATEGORIZED_2025!$C$2:$C$200000) | C13: =SUMPRODUCT((CATEGORIZED_2025!$G$2:$G$200000="COGS")*(TEXT(CATEGORIZED_2025!$A$2:$A$200000,"yyyy-mm")="2025-12")*CATEGORIZED_2025!$C$2:$C$200000) | D13: =SUMPRODUCT((CATEGORIZED_2025!$G$2:$G$200000="Expense")*(TEXT(CATEGORIZED_2025!$A$2:$A$200000,"yyyy-mm")="2025-12")*CATEGORIZED_2025!$C$2:$C$200000) | E13: =B13-C13-D13

Sheet LABOR_2025
A1: Contractor | B1: Total
A2: Bryan | B2: =SUMIFS(CATEGORIZED_2025!$C:$C,CATEGORIZED_2025!$E:$E,"Labor",CATEGORIZED_2025!$J:$J,A2)
A3: Jameson | B3: =SUMIFS(CATEGORIZED_2025!$C:$C,CATEGORIZED_2025!$E:$E,"Labor",CATEGORIZED_2025!$J:$J,A3)
A4: Casey | B4: =SUMIFS(CATEGORIZED_2025!$C:$C,CATEGORIZED_2025!$E:$E,"Labor",CATEGORIZED_2025!$J:$J,A4)
A5: Tony | B5: =SUMIFS(CATEGORIZED_2025!$C:$C,CATEGORIZED_2025!$E:$E,"Labor",CATEGORIZED_2025!$J:$J,A5)
